Workbook

Sheet Sheet1
A1: пн | B1: Описание | C1: Тнвэд | E1: URL | F1: ТНВЭД | G1: Кол-во символов | H1: 107 | I1: Фамилия
A2: 2920 | B2: Термобрюки | D2: https://www.ozon.ru/product/4305517722/ | E2: https://www.ozon.ru/product/4305517722/ | F2: =VLOOKUP(C2,Лист1!$A:$E,2,0) -> #N/A | G2: =LEN(C2) -> 0 | I2: =IF(C2<>"","Куратов","")
A3: 2921 | B3: Рулевая колонка для велосипеда | D3: https://www.ozon.ru/product/5237595642/ | E3: https://www.ozon.ru/product/5237595642/ | F3: =VLOOKUP(C3,Лист1!$A:$C,2,0) -> #N/A | G3: =LEN(C3) -> 0 | I3: =IF(C3<>"","Куратов","")
A4: 2922 | B4: Комплект верхней одежды | D4: https://www.ozon.ru/product/3831485266/ | E4: https://www.ozon.ru/product/3831485266/ | F4: =VLOOKUP(C4,Лист1!$A:$C,2,0) -> #N/A | G4: =LEN(C4) -> 0 | I4: =IF(C4<>"","Куратов","")
A5: 2923 | B5: Музыкальный диск | D5: https://www.ozon.ru/product/4595079628/ | E5: https://www.ozon.ru/product/4595079628/ | F5: =VLOOKUP(C5,Лист1!$A:$C,2,0) -> #N/A | G5: =LEN(C5) -> 0 | I5: =IF(C5<>"","Куратов","")
A6: 2924 | B6: Чехол для смартфона | D6: https://www.ozon.ru/product/5376655389/ | E6: https://www.ozon.ru/product/5376655389/ | F6: =VLOOKUP(C6,Лист1!$A:$C,2,0) -> #N/A | G6: =LEN(C6) -> 0 | I6: =IF(C6<>"","Куратов","")
A7: 2925 | B7: Брюки | D7: https://www.ozon.ru/product/4757243649/ | E7: https://www.ozon.ru/product/4757243649/ | F7: =VLOOKUP(C7,Лист1!$A:$C,2,0) -> #N/A | G7: =LEN(C7) -> 0 | I7: =IF(C7<>"","Куратов","")
A8: 2926 | B8: Ботинки | D8: https://www.ozon.ru/product/3789031698/ | E8: https://www.ozon.ru/product/3789031698/ | F8: =VLOOKUP(C8,Лист1!$A:$C,2,0) -> #N/A | G8: =LEN(C8) -> 0 | I8: =IF(C8<>"","Куратов","")
A9: 2927 | B9: Сервиз чайный, кофейный | D9: https://www.ozon.ru/product/4254840178/ | E9: https://www.ozon.ru/product/4254840178/ | F9: =VLOOKUP(C9,Лист1!$A:$C,2,0) -> #N/A | G9: =LEN(C9) -> 0 | I9: =IF(C9<>"","Куратов","")
A10: 2928 | B10: Фигурка | D10: https://www.ozon.ru/product/5071752816/ | E10: https://www.ozon.ru/product/5071752816/ | F10: =VLOOKUP(C10,Лист1!$A:$C,2,0) -> #N/A | G10: =LEN(C10) -> 0 | I10: =IF(C10<>"","Куратов","")
A11: 2929 | B11: Поддон для дегидратора | D11: https://www.ozon.ru/product/4264625141/ | E11: https://www.ozon.ru/product/4264625141/ | F11: =VLOOKUP(C11,Лист1!$A:$C,2,0) -> #N/A | G11: =LEN(C11) -> 0 | I11: =IF(C11<>"","Куратов","")
A12: 2930 | B12: Брюки | D12: https://www.ozon.ru/product/3431059778/ | E12: https://www.ozon.ru/product/3431059778/ | F12: =VLOOKUP(C12,Лист1!$A:$C,2,0) -> #N/A | G12: =LEN(C12) -> 0 | I12: =IF(C12<>"","Куратов","")
A13: 2931 | B13: Бюстгальтер | D13: https://www.ozon.ru/product/2967893252/ | E13: https://www.ozon.ru/product/2967893252/ | F13: =VLOOKUP(C13,Лист1!$A:$C,2,0) -> #N/A | G13: =LEN(C13) -> 0 | I13: =IF(C13<>"","Куратов","")
A14: 2932 | B14: Лейка для душа | D14: https://www.ozon.ru/product/5170142095/ | E14: https://www.ozon.ru/product/5170142095/ | F14: =VLOOKUP(C14,Лист1!$A:$C,2,0) -> #N/A | G14: =LEN(C14) -> 0 | I14: =IF(C14<>"","Куратов","")
... A101: 3019 | B101: Комплект нижнего белья | D101: https://www.ozon.ru/product/3059732356/ | E101: https://www.ozon.ru/product/3059732356/ | F101: =VLOOKUP(C101,Лист1!$A:$C,2,0) -> #N/A | G101: =LEN(C101) -> 0 | I101: =IF(C101<>"","Куратов","")
F102: =VLOOKUP(C102,Лист1!$A:$C,2,0) -> #N/A | G102: =LEN(C102) -> 0 | I102: =IF(C102<>"","Куратов","")
F103: =VLOOKUP(C103,Лист1!$A:$C,2,0) -> #N/A | G103: =LEN(C103) -> 0 | I103: =IF(C103<>"","Куратов","")
F104: =VLOOKUP(C104,Лист1!$A:$C,2,0) -> #N/A | G104: =LEN(C104) -> 0 | I104: =IF(C104<>"","Куратов","")
F105: =VLOOKUP(C105,Лист1!$A:$C,2,0) -> #N/A | G105: =LEN(C105) -> 0 | I105: =IF(C105<>"","Куратов","")
F106: =VLOOKUP(C106,Лист1!$A:$C,2,0) -> #N/A | G106: =LEN(C106) -> 0 | I106: =IF(C106<>"","Куратов","")
F107: =VLOOKUP(C107,Лист1!$A:$C,2,0) -> #N/A | G107: =LEN(C107) -> 0 | I107: =IF(C107<>"","Куратов","")
F108: =VLOOKUP(C108,Лист1!$A:$C,2,0) -> #N/A | G108: =LEN(C108) -> 0 | I108: =IF(C108<>"","Куратов","")
F109: =VLOOKUP(C109,Лист1!$A:$C,2,0) -> #N/A | G109: =LEN(C109) -> 0 | I109: =IF(C109<>"","Куратов","")
F110: =VLOOKUP(C110,Лист1!$A:$C,2,0) -> #N/A | G110: =LEN(C110) -> 0 | I110: =IF(C110<>"","Куратов","")
F111: =VLOOKUP(C111,Лист1!$A:$C,2,0) -> #N/A | G111: =LEN(C111) -> 0 | I111: =IF(C111<>"","Куратов","")
F112: =VLOOKUP(C112,Лист1!$A:$C,2,0) -> #N/A | G112: =LEN(C112) -> 0 | I112: =IF(C112<>"","Куратов","")
F113: =VLOOKUP(C113,Лист1!$A:$C,2,0) -> #N/A | G113: =LEN(C113) -> 0 | I113: =IF(C113<>"","Куратов","")
... F469: =VLOOKUP(C469,Лист1!$A:$C,2,0) -> #N/A | G469: =LEN(C469) -> 0 | I469: =IF(C469<>"","Куратов","")
F470: =VLOOKUP(C470,Лист1!$A:$C,2,0) -> #N/A | G470: =LEN(C470) -> 0
F471: =VLOOKUP(C471,Лист1!$A:$C,2,0) -> #N/A | G471: =LEN(C471) -> 0
F472: =VLOOKUP(C472,Лист1!$A:$C,2,0) -> #N/A | G472: =LEN(C472) -> 0
F473: =VLOOKUP(C473,Лист1!$A:$C,2,0) -> #N/A | G473: =LEN(C473) -> 0
F474: =VLOOKUP(C474,Лист1!$A:$C,2,0) -> #N/A | G474: =LEN(C474) -> 0
D475: =HYPERLINK(E475) | F475: =VLOOKUP(C475,Лист1!$A:$C,2,0) -> #N/A | G475: =LEN(C475) -> 0
D476: =HYPERLINK(E476) | F476: =VLOOKUP(C476,Лист1!$A:$C,2,0) -> #N/A | G476: =LEN(C476) -> 0
D477: =HYPERLINK(E477) | F477: =VLOOKUP(C477,Лист1!$A:$C,2,0) -> #N/A | G477: =LEN(C477) -> 0
D478: =HYPERLINK(E478) | F478: =VLOOKUP(C478,Лист1!$A:$C,2,0) -> #N/A | G478: =LEN(C478) -> 0
D479: =HYPERLINK(E479) | F479: =VLOOKUP(C479,Лист1!$A:$C,2,0) -> #N/A | G479: =LEN(C479) -> 0
D480: =HYPERLINK(E480) | F480: =VLOOKUP(C480,Лист1!$A:$C,2,0) -> #N/A | G480: =LEN(C480) -> 0
D481: =HYPERLINK(E481) | F481: =VLOOKUP(C481,Лист1!$A:$C,2,0) -> #N/A | G481: =LEN(C481) -> 0
...

Sheet Лист1
A1: Код
A2: 0101210000 | B2: Да
A3: 0101291000 | B3: Да
A4: 0101299000 | B4: Да
A5: 0101300000 | B5: Да
A6: 0101900000 | B6: Да
A7: 0102211000 | B7: Да
A8: 0102213000 | B8: Да
A9: 0102219000 | B9: Да
A10: 0102290500 | B10: Да
A11: 0102291000 | B11: Да
A12: 0102292100 | B12: Да
A13: 0102292900 | B13: Да
... A1657: 0910999900 | B1657: Да
A1658: 1001110000 | B1658: Да
A1659: 1001190000 | B1659: Да
A1660: 1001911000 | B1660: Да
A1661: 1001912000 | B1661: Да
A1662: 1001919000 | B1662: Да
A1663: 1001990000 | B1663: Да
A1664: 1002100000 | B1664: Да
A1665: 1002900000 | B1665: Да
A1666: 1003100000 | B1666: Да
A1667: 1003900000 | B1667: Да
A1668: 1004100000 | B1668: Да
A1669: 1004900000 | B1669: Да
... A13277: 9706900000 | B13277: Да
